Workbook
Name SourceFolder: Parameters!$B$2
Name ReportStart: Parameters!$B$3
Name ReportMonths: Parameters!$B$4

Sheet About
A1: Intangible-asset depreciation model
A2: Synthetic data. Rebuilt from scratch; the production version is proprietary.
A4: How this workbook works
A5: 1. Parameters: set SourceFolder to the full path of the repo's source_files folder.
A6: 2. Paste the Power Query scripts from powerquery/ (see docs/LOAD_QUERIES.md).
A7: 3. Load query MonthlyTotals to sheet PQ_MonthlyTotals, cell A1.
A8: 4. Data > Refresh All. The Check sheet compares Power Query with the Python
A9: reference totals in Expected_MonthlyTotals (tolerance 0.01 per value).
A11: Sheets
A12: AssetRegister - opening register (source data, as in source_files/).
A13: Movements_Clean - movements as cleaned by the Python reference implementation.
A14: Expected_MonthlyTotals - Python reference monthly totals (expected_outputs/).
... A16: Check - formula comparison, one row per month.

Sheet Parameters
A1: Parameter | B1: Value | C1: Used by
A2: SourceFolder | B2: C:\CHANGE-ME\excel-power-query-depreciation\source_files\ | C2: 01_pSourceFolder.pq - folder with asset_register.csv and movements
A3: ReportStart | B3: 45292 | C3: 02_pReportStart.pq - first reporting month
A4: ReportMonths | B4: 24 | C4: 03_pReportMonths.pq - number of reporting months
A6: Each value is a named range; Power Query reads it via Excel.CurrentWorkbook().

Sheet AssetRegister
A1: asset_id | B1: asset_name | C1: category | D1: cost_centre | E1: acquisition_date | F1: cost | G1: useful_life_months | H1: disposal_date
A2: IA-00001 | B2: Network capacity right (2019) | C2: Usage rights | D2: CC-500 | E2: 43652 | F2: 1437812 | G2: 60
A3: IA-00002 | B3: Brand licence (2022) | C3: Trademarks and other rights | D3: CC-400 | E3: 44594 | F3: 181686.3 | G3: 60 | H3: 44751
A4: IA-00003 | B4: Integration layer (2018) | C4: Capitalised development | D4: CC-400 | E4: 43453 | F4: 681035.06 | G4: 48
A5: IA-00004 | B5: Monitoring tool licence (2017) | C5: Software licences | D5: CC-600 | E5: 43033 | F5: 47760.42 | G5: 36
A6: IA-00005 | B6: Site access right (2021) | C6: Usage rights | D6: CC-300 | E6: 44215 | F6: 970372.18 | G6: 60
A7: IA-00006 | B7: Content rights package (2022) | C7: Trademarks and other rights | D7: CC-300 | E7: 44644 | F7: 20503.26 | G7: 60
A8: IA-00007 | B8: Collaboration suite licence (2017) | C8: Software licences | D8: CC-500 | E8: 42820 | F8: 84829.43 | G8: 48
A9: IA-00008 | B9: Collaboration suite licence (2018) | C9: Software licences | D9: CC-500 | E9: 43452 | F9: 32654.36 | G9: 36
A10: IA-00009 | B10: Analytics suite licence (2019) | C10: Software licences | D10: CC-500 | E10: 43760 | F10: 11033.66 | G10: 60
A11: IA-00010 | B11: Duct usage right (2021) | C11: Usage rights | D11: CC-500 | E11: 44416 | F11: 169695.98 | G11: 180
A12: IA-00011 | B12: Network capacity right (2019) | C12: Usage rights | D12: CC-500 | E12: 43502 | F12: 154465.25 | G12: 120
A13: IA-00012 | B13: ERP licence (2016) | C13: Software licences | D13: CC-500 | E13: 42391 | F13: 134981.26 | G13: 48
A14: IA-00013 | B14: Order management feature (2022) | C14: Capitalised development | D14: CC-400 | E14: 44651 | F14: 114740.12 | G14: 36
A15: IA-00014 | B15: ERP licence (2021) | C15: Software licences | D15: CC-600 | E15: 44323 | F15: 32880.06 | G15: 48
... A45: IA-00044 | B45: Monitoring tool licence (2017) | C45: Software licences | D45: CC-500 | E45: 42893 | F45: 58353.4 | G45: 60
A46: IA-00045 | B46: Database licence (2018) | C46: Software licences | D46: CC-600 | E46: 43276 | F46: 129355.96 | G46: 48 | H46: 45255
A47: IA-00046 | B47: Analytics suite licence (2016) | C47: Software licences | D47: CC-200 | E47: 42410 | F47: 11170.02 | G47: 36
A48: IA-00047 | B48: Reporting platform (2016) | C48: Capitalised development | D48: CC-500 | E48: 42725 | F48: 137436.15 | G48: 60
A49: IA-00048 | B49: Security software licence (2022) | C49: Software licences | D49: CC-100 | E49: 44719 | F49: 98036.18 | G49: 60
A50: IA-00049 | B50: ERP licence (2016) | C50: Software licences | D50: CC-300 | E50: 42731 | F50: 253159.33 | G50: 60
A51: IA-00050 | B51: Data warehouse build (2021) | C51: Capitalised development | D51: CC-400 | E51: 44306 | F51: 760113.28 | G51: 36
A52: IA-00051 | B52: Brand licence (2016) | C52: Trademarks and other rights | D52: CC-400 | E52: 42442 | F52: 77528.36 | G52: 120
A53: IA-00052 | B53: ERP licence (2019) | C53: Software licences | D53: CC-100 | E53: 43594 | F53: 300947.09 | G53: 48
A54: IA-00053 | B54: Patent licence (2022) | C54: Trademarks and other rights | D54: CC-500 | E54: 44720 | F54: 56075.53 | G54: 120
A55: IA-00054 | B55: ERP licence (2022) | C55: Software licences | D55: CC-300 | E55: 44793 | F55: 141086.41 | G55: 36
A56: IA-00055 | B56: Integration layer (2020) | C56: Capitalised development | D56: CC-400 | E56: 44140 | F56: 543984.96 | G56: 36
A57: IA-00056 | B57: Database licence (2019) | C57: Software licences | D57: CC-600 | E57: 43614 | F57: 73810.01 | G57: 60
A58: IA-00057 | B58: Reporting platform (2017) | C58: Capitalised development | D58: CC-500 | E58: 43094 | F58: 49236.05 | G58: 60
... A126: IA-00125 | B126: Self-care portal release (2019) | C126: Capitalised development | D126: CC-200 | E126: 43811 | F126: 27548.03 | G126: 60
A127: IA-00126 | B127: Integration layer (2021) | C127: Capitalised development | D127: CC-500 | E127: 44266 | F127: 256459.27 | G127: 60 | H127: 44786
A128: IA-00127 | B128: Collaboration suite licence (2018) | C128: Software licences | D128: CC-300 | E128: 43441 | F128: 44650.53 | G128: 60
A129: IA-00128 | B129: Integration layer (2022) | C129: Capitalised development | D129: CC-300 | E129: 44615 | F129: 512380.64 | G129: 48
A130: IA-00129 | B130: Domain portfolio (2020) | C130: Trademarks and other rights | D130: CC-300 | E130: 44085 | F130: 230245.12 | G130: 120
A131: IA-00130 | B131: Order management feature (2016) | C131: Capitalised development | D131: CC-600 | E131: 42676 | F131: 91184.7 | G131: 60
A132: IA-00131 | B132: Data warehouse build (2017) | C132: Capitalised development | D132: CC-200 | E132: 42888 | F132: 72649.12 | G132: 36
A133: IA-00132 | B133: Brand licence (2019) | C133: Trademarks and other rights | D133: CC-100 | E133: 43679 | F133: 31094.93 | G133: 120
A134: IA-00133 | B134: Analytics suite licence (2018) | C134: Software licences | D134: CC-400 | E134: 43182 | F134: 92759.12 | G134: 60
A135: IA-00134 | B135: Reporting platform (2019) | C135: Capitalised development | D135: CC-400 | E135: 43765 | F135: 362944.18 | G135: 60
A136: IA-00135 | B136: Order management feature (2023) | C136: Capitalised development | D136: CC-600 | E136: 45184 | F136: 392510 | G136: 36
...

Sheet Movements_Clean
A1: asset_id | B1: movement_type | C1: movement_date | D1: amount | E1: asset_name | F1: category | G1: useful_life_months | H1: cost_centre | I1: source_file
A2: IA-00335 | B2: ADDITION | C2: 45292 | D2: 27599.55 | E2: Database licence (2024) | F2: Software licences | G2: 48 | H2: CC-500 | I2: movements_2024_01.csv
A3: IA-00378 | B3: ADDITION | C3: 45307 | D3: 142119.92 | E3: Order management feature (2024) | F3: Capitalised development | G3: 48 | H3: CC-500 | I3: movements_2024_01.csv
A4: IA-00400 | B4: ADDITION | C4: 45310 | D4: 9875.69 | E4: Database licence (2024) | F4: Software licences | G4: 60 | H4: CC-200 | I4: movements_2024_01.csv
A5: IA-00389 | B5: ADDITION | C5: 45314 | D5: 23068.11 | E5: Analytics suite licence (2024) | F5: Software licences | G5: 60 | H5: CC-200 | I5: movements_2024_01.csv
A6: IA-00285 | B6: TRANSFER | C6: 45320 | H6: CC-100 | I6: movements_2024_01.csv
A7: IA-00349 | B7: ADDITION | C7: 45332 | D7: 53923.63 | E7: Monitoring tool licence (2024) | F7: Software licences | G7: 36 | H7: CC-100 | I7: movements_2024_02.csv
A8: IA-00191 | B8: TRANSFER | C8: 45341 | H8: CC-600 | I8: movements_2024_02.csv
A9: IA-00329 | B9: ADDITION | C9: 45355 | D9: 10811.86 | E9: Database licence (2024) | F9: Software licences | G9: 60 | H9: CC-300 | I9: movements_2024_03.csv
A10: IA-00312 | B10: TRANSFER | C10: 45356 | H10: CC-500 | I10: movements_2024_03.csv
A11: IA-00379 | B11: ADDITION | C11: 45365 | D11: 132526.84 | E11: Monitoring tool licence (2024) | F11: Software licences | G11: 36 | H11: CC-600 | I11: movements_2024_03.csv
A12: IA-00357 | B12: ADDITION | C12: 45367 | D12: 121995.28 | E12: Mobile app release (2024) | F12: Capitalised development | G12: 60 | H12: CC-400 | I12: movements_2024_03.csv
A13: IA-00188 | B13: TRANSFER | C13: 45368 | H13: CC-300 | I13: movements_2024_03.csv
A14: IA-00376 | B14: ADDITION | C14: 45371 | D14: 21076.91 | E14: Data warehouse build (2024) | F14: Capitalised development | G14: 36 | H14: CC-300 | I14: movements_2024_03.csv
A15: IA-00029 | B15: TRANSFER | C15: 45378 | H15: CC-600 | I15: movements_2024_03.csv
A16: IA-00346 | B16: ADDITION | C16: 45385 | D16: 9301.24 | E16: Database licence (2024) | F16: Software licences | G16: 60 | H16: CC-400 | I16: movements_2024_04.csv
A17: IA-00374 | B17: ADDITION | C17: 45394 | D17: 28749.87 | E17: ERP licence (2024) | F17: Software licences | G17: 48 | H17: CC-500 | I17: movements_2024_04.csv
A18: IA-00303 | B18: DISPOSAL | C18: 45395 | E18: Monitoring tool licence (2021) | I18: movements_2024_04.csv
A19: IA-00373 | B19: ADDITION | C19: 45395 | D19: 35765.08 | E19: Self-care portal release (2024) | F19: Capitalised development | G19: 36 | H19: CC-500 | I19: movements_2024_04.csv
A20: IA-00382 | B20: ADDITION | C20: 45399 | D20: 71941.91 | E20: Order management feature (2024) | F20: Capitalised development | G20: 60 | H20: CC-100 | I20: movements_2024_04.csv
A21: IA-00184 | B21: DISPOSAL | C21: 45402 | E21: Site access right (2016) | I21: movements_2024_04.csv
A22: IA-00369 | B22: ADDITION | C22: 45402 | D22: 13855.61 | E22: Patent licence (2024) | F22: Trademarks and other rights | G22: 120 | H22: CC-500 | I22: movements_2024_04.csv
A23: IA-00348 | B23: ADDITION | C23: 45421 | D23: 75122.56 | E23: ERP licence (2024) | F23: Software licences | G23: 36 | H23: CC-600 | I23: movements_2024_05.csv
A24: IA-00104 | B24: TRANSFER | C24: 45427 | H24: CC-400 | I24: movements_2024_05.csv
A25: IA-00392 | B25: ADDITION | C25: 45448 | D25: 615279.1 | E25: Integration layer (2024) | F25: Capitalised development | G25: 48 | H25: CC-300 | I25: movements_2024_06.csv
A26: IA-00358 | B26: ADDITION | C26: 45455 | D26: 30582.19 | E26: CRM licence (2024) | F26: Software licences | G26: 48 | H26: CC-100 | I26: movements_2024_06.csv
A27: IA-00347 | B27: ADDITION | C27: 45458 | D27: 119318.15 | E27: Collaboration suite licence (2024) | F27: Software licences | G27: 36 | H27: CC-400 | I27: movements_2024_06.csv
A28: IA-00338 | B28: ADDITION | C28: 45460 | D28: 1729351.2 | E28: Duct usage right (2024) | F28: Usage rights | G28: 120 | H28: CC-600 | I28: movements_2024_06.csv
A29: IA-00076 | B29: TRANSFER | C29: 45477 | H29: CC-100 | I29: movements_2024_07.csv
A30: IA-00279 | B30: DISPOSAL | C30: 45479 | E30: Database licence (2016) | I30: movements_2024_07.csv
A31: IA-00129 | B31: DISPOSAL | C31: 45480 | E31: Domain portfolio (2020) | I31: movements_2024_07.csv
A32: IA-00323 | B32: ADDITION | C32: 45482 | D32: 91162.35 | E32: Content distribution right (2024) | F32: Usage rights | G32: 180 | H32: CC-200 | I32: movements_2024_07.csv
A33: IA-00340 | B33: ADDITION | C33: 45484 | D33: 54096.9 | E33: Database licence (2024) | F33: Software licences | G33: 60 | H33: CC-500 | I33: movements_2024_07.csv
A34: IA-00385 | B34: ADDITION | C34: 45486 | D34: 64200.83 | E34: Brand licence (2024) | F34: Trademarks and other rights | G34: 120 | H34: CC-100 | I34: movements_2024_07.csv
A35: IA-00028 | B35: DISPOSAL | C35: 45489 | E35: Security software licence (2019) | I35: movements_2024_07.csv
A36: IA-00398 | B36: ADDITION | C36: 45492 | D36: 4632.09 | E36: ERP licence (2024) | F36: Software licences | G36: 36 | H36: CC-300 | I36: movements_2024_07.csv
A37: IA-00375 | B37: ADDITION | C37: 45496 | D37: 22594.61 | E37: Mobile app release (2024) | F37: Capitalised development | G37: 36 | H37: CC-400 | I37: movements_2024_07.csv
A38: IA-00325 | B38: ADDITION | C38: 45516 | D38: 116682.28 | E38: Duct usage right (2024) | F38: Usage rights | G38: 120 | H38: CC-500 | I38: movements_2024_08.csv
A39: IA-00373 | B39: TRANSFER | C39: 45522 | H39: CC-600 | I39: movements_2024_08.csv
A40: IA-00344 | B40: ADDITION | C40: 45526 | D40: 46226.14 | E40: Monitoring tool licence (2024) | F40: Software licences | G40: 48 | H40: CC-100 | I40: movements_2024_08.csv
...

Sheet Expected_MonthlyTotals
A1: month_start | B1: asset_rows | C1: opening_cost | D1: additions | E1: disposals_cost | F1: closing_cost | G1: opening_acc_dep | H1: depreciation | I1: disposal_acc_dep | J1: closing_acc_dep | K1: closing_nbv | L1: disposal_nbv
A2: 45292 | B2: 312 | C2: 55331277 | D2: 202663.27 | E2: 0 | F2: 55533940 | G2: 35855503 | H2: 584437.96 | I2: 0 | J2: 36439940 | K2: 19094000 | L2: 0
A3: 45323 | B3: 313 | C3: 55533940 | D3: 53923.63 | E3: 0 | F3: 55587864 | G3: 36439940 | H3: 564123.36 | I3: 0 | J3: 37004064 | K3: 18583800 | L3: 0
A4: 45352 | B4: 317 | C4: 55587864 | D4: 286410.89 | E4: 0 | F4: 55874275 | G4: 37004064 | H4: 563304.38 | I4: 0 | J4: 37567368 | K4: 18306907 | L4: 0
A5: 45383 | B5: 322 | C5: 55874275 | D5: 159613.71 | E5: 535687.89 | F5: 55498201 | G5: 37567368 | H5: 558348.71 | I5: 535231.93 | J5: 37590485 | K5: 17907716 | L5: 455.96
A6: 45413 | B6: 321 | C6: 55498201 | D6: 75122.56 | E6: 0 | F6: 55573323 | G6: 37590485 | H6: 546167.37 | I6: 0 | J6: 38136652 | K6: 17436671 | L6: 0
A7: 45444 | B7: 325 | C7: 55573323 | D7: 2494530.6 | E7: 0 | F7: 58067854 | G7: 38136652 | H7: 556257 | I7: 0 | J7: 38692909 | K7: 19374945 | L7: 0
A8: 45474 | B8: 330 | C8: 58067854 | D8: 236686.78 | E8: 298929.03 | F8: 58005612 | G8: 38692909 | H8: 540704.55 | I8: 156676.33 | J8: 39076938 | K8: 18928674 | L8: 142252.7
A9: 45505 | B9: 329 | C9: 58005612 | D9: 162908.42 | E9: 226474.69 | F9: 57942045 | G9: 39076938 | H9: 535801.83 | I9: 86332.31 | J9: 39526407 | K9: 18415638 | L9: 140142.38
A10: 45536 | B10: 330 | C10: 57942045 | D10: 128676.81 | E10: 28612.18 | F10: 58042110 | G10: 39526407 | H10: 532665.08 | I10: 28612.18 | J10: 40030460 | K10: 18011650 | L10: 0
A11: 45566 | B11: 331 | C11: 58042110 | D11: 459542.09 | E11: 47284.06 | F11: 58454368 | G11: 40030460 | H11: 534190.25 | I11: 38148.29 | J11: 40526502 | K11: 17927866 | L11: 9135.77
A12: 45597 | B12: 331 | C12: 58454368 | D12: 192670.64 | E12: 530995.41 | F12: 58116043 | G12: 40526502 | H12: 531182.86 | I12: 480343.38 | J12: 40577341 | K12: 17538702 | L12: 50652.03
A13: 45627 | B13: 335 | C13: 58116043 | D13: 1309872.5 | E13: 0 | F13: 59425916 | G13: 40577341 | H13: 547016.4 | I13: 0 | J13: 41124358 | K13: 18301558 | L13: 0
... A25: 45992 | B25: 360 | C25: 62706644 | D25: 2163579.4 | E25: 868692.33 | F25: 64001531 | G25: 43520124 | H25: 540383.46 | I25: 383826.28 | J25: 43676681 | K25: 20324850 | L25: 484866.05

Sheet PQ_MonthlyTotals

Sheet Check
A1: Check: Power Query MonthlyTotals vs Python reference (expected_outputs)
A2: Overall status | B2: =IF(NOT($B$3),"NOT LOADED - load query MonthlyTotals to PQ_MonthlyTotals!A1",IF(AND($B$5,COUNTIF(W8:W31,"OK")=24),"ALL CHECKS PASS","MISMATCH - see rows below"))
A3: PQ output loaded? | B3: =LEN(PQ_MonthlyTotals!$A$1)>0
A4: Tolerance per value | B4: 0.01
A5: PQ columns in expected order? | B5: =AND(PQ_MonthlyTotals!A1="month_start",PQ_MonthlyTotals!B1="asset_rows",PQ_MonthlyTotals!C1="opening_cost",PQ_MonthlyTotals!D1="additions",PQ_MonthlyTotals!E1="disposals_cost",PQ_MonthlyTotals!F1="closing_cost",PQ_MonthlyTotals!G1="opening_acc_dep",PQ_MonthlyTotals!H1="depreciation",PQ_MonthlyTotals!I1="disposal_acc_dep",PQ_MonthlyTotals!J1="closing_acc_dep",PQ_MonthlyTotals!K1="closing_nbv",PQ_MonthlyTotals!L1="disposal_nbv")
B6: asset_rows | E6: additions | H6: disposals_cost | K6: depreciation | N6: closing_cost | Q6: closing_acc_dep | T6: closing_nbv
A7: month_start | B7: Expected | C7: Power Query | D7: Difference | E7: Expected | F7: Power Query | G7: Difference | H7: Expected | I7: Power Query | J7: Difference | K7: Expected | L7: Power Query | M7: Difference | N7: Expected | O7: Power Query | P7: Difference | Q7: Expected | R7: Power Query | S7: Difference | T7: Expected | U7: Power Query | V7: Difference | W7: Row status
A8: =Expected_MonthlyTotals!A2 | B8: =Expected_MonthlyTotals!B2 | C8: =IF($B$3,SUMIFS(PQ_MonthlyTotals!$B$2:$B$2000,PQ_MonthlyTotals!$A$2:$A$2000,$A8),"") | D8: =IF($B$3,C8-B8,"") | E8: =Expected_MonthlyTotals!D2 | F8: =IF($B$3,SUMIFS(PQ_MonthlyTotals!$D$2:$D$2000,PQ_MonthlyTotals!$A$2:$A$2000,$A8),"") | G8: =IF($B$3,F8-E8,"") | H8: =Expected_MonthlyTotals!E2 | I8: =IF($B$3,SUMIFS(PQ_MonthlyTotals!$E$2:$E$2000,PQ_MonthlyTotals!$A$2:$A$2000,$A8),"") | J8: =IF($B$3,I8-H8,"") | K8: =Expected_MonthlyTotals!H2 | L8: =IF($B$3,SUMIFS(PQ_MonthlyTotals!$H$2:$H$2000,PQ_MonthlyTotals!$A$2:$A$2000,$A8),"") | M8: =IF($B$3,L8-K8,"") | N8: =Expected_MonthlyTotals!F2 | O8: =IF($B$3,SUMIFS(PQ_MonthlyTotals!$F$2:$F$2000,PQ_MonthlyTotals!$A$2:$A$2000,$A8),"") | P8: =IF($B$3,O8-N8,"") | Q8: =Expected_MonthlyTotals!J2 | R8: =IF($B$3,SUMIFS(PQ_MonthlyTotals!$J$2:$J$2000,PQ_MonthlyTotals!$A$2:$A$2000,$A8),"") | S8: =IF($B$3,R8-Q8,"") | T8: =Expected_MonthlyTotals!K2 | U8: =IF($B$3,SUMIFS(PQ_MonthlyTotals!$K$2:$K$2000,PQ_MonthlyTotals!$A$2:$A$2000,$A8),"") | V8: =IF($B$3,U8-T8,"") | W8: =IF(NOT($B$3),"NOT LOADED",IF(AND(ABS(D8)<=$B$4,ABS(G8)<=$B$4,ABS(J8)<=$B$4,ABS(M8)<=$B$4,ABS(P8)<=$B$4,ABS(S8)<=$B$4,ABS(V8)<=$B$4),"OK","MISMATCH"))
A9: =Expected_MonthlyTotals!A3 | B9: =Expected_MonthlyTotals!B3 | C9: =IF($B$3,SUMIFS(PQ_MonthlyTotals!$B$2:$B$2000,PQ_MonthlyTotals!$A$2:$A$2000,$A9),"") | D9: =IF($B$3,C9-B9,"") | E9: =Expected_MonthlyTotals!D3 | F9: =IF($B$3,SUMIFS(PQ_MonthlyTotals!$D$2:$D$2000,PQ_MonthlyTotals!$A$2:$A$2000,$A9),"") | G9: =IF($B$3,F9-E9,"") | H9: =Expected_MonthlyTotals!E3 | I9: =IF($B$3,SUMIFS(PQ_MonthlyTotals!$E$2:$E$2000,PQ_MonthlyTotals!$A$2:$A$2000,$A9),"") | J9: =IF($B$3,I9-H9,"") | K9: =Expected_MonthlyTotals!H3 | L9: =IF($B$3,SUMIFS(PQ_MonthlyTotals!$H$2:$H$2000,PQ_MonthlyTotals!$A$2:$A$2000,$A9),"") | M9: =IF($B$3,L9-K9,"") | N9: =Expected_MonthlyTotals!F3 | O9: =IF($B$3,SUMIFS(PQ_MonthlyTotals!$F$2:$F$2000,PQ_MonthlyTotals!$A$2:$A$2000,$A9),"") | P9: =IF($B$3,O9-N9,"") | Q9: =Expected_MonthlyTotals!J3 | R9: =IF($B$3,SUMIFS(PQ_MonthlyTotals!$J$2:$J$2000,PQ_MonthlyTotals!$A$2:$A$2000,$A9),"") | S9: =IF($B$3,R9-Q9,"") | T9: =Expected_MonthlyTotals!K3 | U9: =IF($B$3,SUMIFS(PQ_MonthlyTotals!$K$2:$K$2000,PQ_MonthlyTotals!$A$2:$A$2000,$A9),"") | V9: =IF($B$3,U9-T9,"") | W9: =IF(NOT($B$3),"NOT LOADED",IF(AND(ABS(D9)<=$B$4,ABS(G9)<=$B$4,ABS(J9)<=$B$4,ABS(M9)<=$B$4,ABS(P9)<=$B$4,ABS(S9)<=$B$4,ABS(V9)<=$B$4),"OK","MISMATCH"))
A10: =Expected_MonthlyTotals!A4 | B10: =Expected_MonthlyTotals!B4 | C10: =IF($B$3,SUMIFS(PQ_MonthlyTotals!$B$2:$B$2000,PQ_MonthlyTotals!$A$2:$A$2000,$A10),"") | D10: =IF($B$3,C10-B10,"") | E10: =Expected_MonthlyTotals!D4 | F10: =IF($B$3,SUMIFS(PQ_MonthlyTotals!$D$2:$D$2000,PQ_MonthlyTotals!$A$2:$A$2000,$A10),"") | G10: =IF($B$3,F10-E10,"") | H10: =Expected_MonthlyTotals!E4 | I10: =IF($B$3,SUMIFS(PQ_MonthlyTotals!$E$2:$E$2000,PQ_MonthlyTotals!$A$2:$A$2000,$A10),"") | J10: =IF($B$3,I10-H10,"") | K10: =Expected_MonthlyTotals!H4 | L10: =IF($B$3,SUMIFS(PQ_MonthlyTotals!$H$2:$H$2000,PQ_MonthlyTotals!$A$2:$A$2000,$A10),"") | M10: =IF($B$3,L10-K10,"") | N10: =Expected_MonthlyTotals!F4 | O10: =IF($B$3,SUMIFS(PQ_MonthlyTotals!$F$2:$F$2000,PQ_MonthlyTotals!$A$2:$A$2000,$A10),"") | P10: =IF($B$3,O10-N10,"") | Q10: =Expected_MonthlyTotals!J4 | R10: =IF($B$3,SUMIFS(PQ_MonthlyTotals!$J$2:$J$2000,PQ_MonthlyTotals!$A$2:$A$2000,$A10),"") | S10: =IF($B$3,R10-Q10,"") | T10: =Expected_MonthlyTotals!K4 | U10: =IF($B$3,SUMIFS(PQ_MonthlyTotals!$K$2:$K$2000,PQ_MonthlyTotals!$A$2:$A$2000,$A10),"") | V10: =IF($B$3,U10-T10,"") | W10: =IF(NOT($B$3),"NOT LOADED",IF(AND(ABS(D10)<=$B$4,ABS(G10)<=$B$4,ABS(J10)<=$B$4,ABS(M10)<=$B$4,ABS(P10)<=$B$4,ABS(S10)<=$B$4,ABS(V10)<=$B$4),"OK","MISMATCH"))
A11: =Expected_MonthlyTotals!A5 | B11: =Expected_MonthlyTotals!B5 | C11: =IF($B$3,SUMIFS(PQ_MonthlyTotals!$B$2:$B$2000,PQ_MonthlyTotals!$A$2:$A$2000,$A11),"") | D11: =IF($B$3,C11-B11,"") | E11: =Expected_MonthlyTotals!D5 | F11: =IF($B$3,SUMIFS(PQ_MonthlyTotals!$D$2:$D$2000,PQ_MonthlyTotals!$A$2:$A$2000,$A11),"") | G11: =IF($B$3,F11-E11,"") | H11: =Expected_MonthlyTotals!E5 | I11: =IF($B$3,SUMIFS(PQ_MonthlyTotals!$E$2:$E$2000,PQ_MonthlyTotals!$A$2:$A$2000,$A11),"") | J11: =IF($B$3,I11-H11,"") | K11: =Expected_MonthlyTotals!H5 | L11: =IF($B$3,SUMIFS(PQ_MonthlyTotals!$H$2:$H$2000,PQ_MonthlyTotals!$A$2:$A$2000,$A11),"") | M11: =IF($B$3,L11-K11,"") | N11: =Expected_MonthlyTotals!F5 | O11: =IF($B$3,SUMIFS(PQ_MonthlyTotals!$F$2:$F$2000,PQ_MonthlyTotals!$A$2:$A$2000,$A11),"") | P11: =IF($B$3,O11-N11,"") | Q11: =Expected_MonthlyTotals!J5 | R11: =IF($B$3,SUMIFS(PQ_MonthlyTotals!$J$2:$J$2000,PQ_MonthlyTotals!$A$2:$A$2000,$A11),"") | S11: =IF($B$3,R11-Q11,"") | T11: =Expected_MonthlyTotals!K5 | U11: =IF($B$3,SUMIFS(PQ_MonthlyTotals!$K$2:$K$2000,PQ_MonthlyTotals!$A$2:$A$2000,$A11),"") | V11: =IF($B$3,U11-T11,"") | W11: =IF(NOT($B$3),"NOT LOADED",IF(AND(ABS(D11)<=$B$4,ABS(G11)<=$B$4,ABS(J11)<=$B$4,ABS(M11)<=$B$4,ABS(P11)<=$B$4,ABS(S11)<=$B$4,ABS(V11)<=$B$4),"OK","MISMATCH"))
A12: =Expected_MonthlyTotals!A6 | B12: =Expected_MonthlyTotals!B6 | C12: =IF($B$3,SUMIFS(PQ_MonthlyTotals!$B$2:$B$2000,PQ_MonthlyTotals!$A$2:$A$2000,$A12),"") | D12: =IF($B$3,C12-B12,"") | E12: =Expected_MonthlyTotals!D6 | F12: =IF($B$3,SUMIFS(PQ_MonthlyTotals!$D$2:$D$2000,PQ_MonthlyTotals!$A$2:$A$2000,$A12),"") | G12: =IF($B$3,F12-E12,"") | H12: =Expected_MonthlyTotals!E6 | I12: =IF($B$3,SUMIFS(PQ_MonthlyTotals!$E$2:$E$2000,PQ_MonthlyTotals!$A$2:$A$2000,$A12),"") | J12: =IF($B$3,I12-H12,"") | K12: =Expected_MonthlyTotals!H6 | L12: =IF($B$3,SUMIFS(PQ_MonthlyTotals!$H$2:$H$2000,PQ_MonthlyTotals!$A$2:$A$2000,$A12),"") | M12: =IF($B$3,L12-K12,"") | N12: =Expected_MonthlyTotals!F6 | O12: =IF($B$3,SUMIFS(PQ_MonthlyTotals!$F$2:$F$2000,PQ_MonthlyTotals!$A$2:$A$2000,$A12),"") | P12: =IF($B$3,O12-N12,"") | Q12: =Expected_MonthlyTotals!J6 | R12: =IF($B$3,SUMIFS(PQ_MonthlyTotals!$J$2:$J$2000,PQ_MonthlyTotals!$A$2:$A$2000,$A12),"") | S12: =IF($B$3,R12-Q12,"") | T12: =Expected_MonthlyTotals!K6 | U12: =IF($B$3,SUMIFS(PQ_MonthlyTotals!$K$2:$K$2000,PQ_MonthlyTotals!$A$2:$A$2000,$A12),"") | V12: =IF($B$3,U12-T12,"") | W12: =IF(NOT($B$3),"NOT LOADED",IF(AND(ABS(D12)<=$B$4,ABS(G12)<=$B$4,ABS(J12)<=$B$4,ABS(M12)<=$B$4,ABS(P12)<=$B$4,ABS(S12)<=$B$4,ABS(V12)<=$B$4),"OK","MISMATCH"))
A13: =Expected_MonthlyTotals!A7 | B13: =Expected_MonthlyTotals!B7 | C13: =IF($B$3,SUMIFS(PQ_MonthlyTotals!$B$2:$B$2000,PQ_MonthlyTotals!$A$2:$A$2000,$A13),"") | D13: =IF($B$3,C13-B13,"") | E13: =Expected_MonthlyTotals!D7 | F13: =IF($B$3,SUMIFS(PQ_MonthlyTotals!$D$2:$D$2000,PQ_MonthlyTotals!$A$2:$A$2000,$A13),"") | G13: =IF($B$3,F13-E13,"") | H13: =Expected_MonthlyTotals!E7 | I13: =IF($B$3,SUMIFS(PQ_MonthlyTotals!$E$2:$E$2000,PQ_MonthlyTotals!$A$2:$A$2000,$A13),"") | J13: =IF($B$3,I13-H13,"") | K13: =Expected_MonthlyTotals!H7 | L13: =IF($B$3,SUMIFS(PQ_MonthlyTotals!$H$2:$H$2000,PQ_MonthlyTotals!$A$2:$A$2000,$A13),"") | M13: =IF($B$3,L13-K13,"") | N13: =Expected_MonthlyTotals!F7 | O13: =IF($B$3,SUMIFS(PQ_MonthlyTotals!$F$2:$F$2000,PQ_MonthlyTotals!$A$2:$A$2000,$A13),"") | P13: =IF($B$3,O13-N13,"") | Q13: =Expected_MonthlyTotals!J7 | R13: =IF($B$3,SUMIFS(PQ_MonthlyTotals!$J$2:$J$2000,PQ_MonthlyTotals!$A$2:$A$2000,$A13),"") | S13: =IF($B$3,R13-Q13,"") | T13: =Expected_MonthlyTotals!K7 | U13: =IF($B$3,SUMIFS(PQ_MonthlyTotals!$K$2:$K$2000,PQ_MonthlyTotals!$A$2:$A$2000,$A13),"") | V13: =IF($B$3,U13-T13,"") | W13: =IF(NOT($B$3),"NOT LOADED",IF(AND(ABS(D13)<=$B$4,ABS(G13)<=$B$4,ABS(J13)<=$B$4,ABS(M13)<=$B$4,ABS(P13)<=$B$4,ABS(S13)<=$B$4,ABS(V13)<=$B$4),"OK","MISMATCH"))
A14: =Expected_MonthlyTotals!A8 | B14: =Expected_MonthlyTotals!B8 | C14: =IF($B$3,SUMIFS(PQ_MonthlyTotals!$B$2:$B$2000,PQ_MonthlyTotals!$A$2:$A$2000,$A14),"") | D14: =IF($B$3,C14-B14,"") | E14: =Expected_MonthlyTotals!D8 | F14: =IF($B$3,SUMIFS(PQ_MonthlyTotals!$D$2:$D$2000,PQ_MonthlyTotals!$A$2:$A$2000,$A14),"") | G14: =IF($B$3,F14-E14,"") | H14: =Expected_MonthlyTotals!E8 | I14: =IF($B$3,SUMIFS(PQ_MonthlyTotals!$E$2:$E$2000,PQ_MonthlyTotals!$A$2:$A$2000,$A14),"") | J14: =IF($B$3,I14-H14,"") | K14: =Expected_MonthlyTotals!H8 | L14: =IF($B$3,SUMIFS(PQ_MonthlyTotals!$H$2:$H$2000,PQ_MonthlyTotals!$A$2:$A$2000,$A14),"") | M14: =IF($B$3,L14-K14,"") | N14: =Expected_MonthlyTotals!F8 | O14: =IF($B$3,SUMIFS(PQ_MonthlyTotals!$F$2:$F$2000,PQ_MonthlyTotals!$A$2:$A$2000,$A14),"") | P14: =IF($B$3,O14-N14,"") | Q14: =Expected_MonthlyTotals!J8 | R14: =IF($B$3,SUMIFS(PQ_MonthlyTotals!$J$2:$J$2000,PQ_MonthlyTotals!$A$2:$A$2000,$A14),"") | S14: =IF($B$3,R14-Q14,"") | T14: =Expected_MonthlyTotals!K8 | U14: =IF($B$3,SUMIFS(PQ_MonthlyTotals!$K$2:$K$2000,PQ_MonthlyTotals!$A$2:$A$2000,$A14),"") | V14: =IF($B$3,U14-T14,"") | W14: =IF(NOT($B$3),"NOT LOADED",IF(AND(ABS(D14)<=$B$4,ABS(G14)<=$B$4,ABS(J14)<=$B$4,ABS(M14)<=$B$4,ABS(P14)<=$B$4,ABS(S14)<=$B$4,ABS(V14)<=$B$4),"OK","MISMATCH"))
A15: =Expected_MonthlyTotals!A9 | B15: =Expected_MonthlyTotals!B9 | C15: =IF($B$3,SUMIFS(PQ_MonthlyTotals!$B$2:$B$2000,PQ_MonthlyTotals!$A$2:$A$2000,$A15),"") | D15: =IF($B$3,C15-B15,"") | E15: =Expected_MonthlyTotals!D9 | F15: =IF($B$3,SUMIFS(PQ_MonthlyTotals!$D$2:$D$2000,PQ_MonthlyTotals!$A$2:$A$2000,$A15),"") | G15: =IF($B$3,F15-E15,"") | H15: =Expected_MonthlyTotals!E9 | I15: =IF($B$3,SUMIFS(PQ_MonthlyTotals!$E$2:$E$2000,PQ_MonthlyTotals!$A$2:$A$2000,$A15),"") | J15: =IF($B$3,I15-H15,"") | K15: =Expected_MonthlyTotals!H9 | L15: =IF($B$3,SUMIFS(PQ_MonthlyTotals!$H$2:$H$2000,PQ_MonthlyTotals!$A$2:$A$2000,$A15),"") | M15: =IF($B$3,L15-K15,"") | N15: =Expected_MonthlyTotals!F9 | O15: =IF($B$3,SUMIFS(PQ_MonthlyTotals!$F$2:$F$2000,PQ_MonthlyTotals!$A$2:$A$2000,$A15),"") | P15: =IF($B$3,O15-N15,"") | Q15: =Expected_MonthlyTotals!J9 | R15: =IF($B$3,SUMIFS(PQ_MonthlyTotals!$J$2:$J$2000,PQ_MonthlyTotals!$A$2:$A$2000,$A15),"") | S15: =IF($B$3,R15-Q15,"") | T15: =Expected_MonthlyTotals!K9 | U15: =IF($B$3,SUMIFS(PQ_MonthlyTotals!$K$2:$K$2000,PQ_MonthlyTotals!$A$2:$A$2000,$A15),"") | V15: =IF($B$3,U15-T15,"") | W15: =IF(NOT($B$3),"NOT LOADED",IF(AND(ABS(D15)<=$B$4,ABS(G15)<=$B$4,ABS(J15)<=$B$4,ABS(M15)<=$B$4,ABS(P15)<=$B$4,ABS(S15)<=$B$4,ABS(V15)<=$B$4),"OK","MISMATCH"))
A16: =Expected_MonthlyTotals!A10 | B16: =Expected_MonthlyTotals!B10 | C16: =IF($B$3,SUMIFS(PQ_MonthlyTotals!$B$2:$B$2000,PQ_MonthlyTotals!$A$2:$A$2000,$A16),"") | D16: =IF($B$3,C16-B16,"") | E16: =Expected_MonthlyTotals!D10 | F16: =IF($B$3,SUMIFS(PQ_MonthlyTotals!$D$2:$D$2000,PQ_MonthlyTotals!$A$2:$A$2000,$A16),"") | G16: =IF($B$3,F16-E16,"") | H16: =Expected_MonthlyTotals!E10 | I16: =IF($B$3,SUMIFS(PQ_MonthlyTotals!$E$2:$E$2000,PQ_MonthlyTotals!$A$2:$A$2000,$A16),"") | J16: =IF($B$3,I16-H16,"") | K16: =Expected_MonthlyTotals!H10 | L16: =IF($B$3,SUMIFS(PQ_MonthlyTotals!$H$2:$H$2000,PQ_MonthlyTotals!$A$2:$A$2000,$A16),"") | M16: =IF($B$3,L16-K16,"") | N16: =Expected_MonthlyTotals!F10 | O16: =IF($B$3,SUMIFS(PQ_MonthlyTotals!$F$2:$F$2000,PQ_MonthlyTotals!$A$2:$A$2000,$A16),"") | P16: =IF($B$3,O16-N16,"") | Q16: =Expected_MonthlyTotals!J10 | R16: =IF($B$3,SUMIFS(PQ_MonthlyTotals!$J$2:$J$2000,PQ_MonthlyTotals!$A$2:$A$2000,$A16),"") | S16: =IF($B$3,R16-Q16,"") | T16: =Expected_MonthlyTotals!K10 | U16: =IF($B$3,SUMIFS(PQ_MonthlyTotals!$K$2:$K$2000,PQ_MonthlyTotals!$A$2:$A$2000,$A16),"") | V16: =IF($B$3,U16-T16,"") | W16: =IF(NOT($B$3),"NOT LOADED",IF(AND(ABS(D16)<=$B$4,ABS(G16)<=$B$4,ABS(J16)<=$B$4,ABS(M16)<=$B$4,ABS(P16)<=$B$4,ABS(S16)<=$B$4,ABS(V16)<=$B$4),"OK","MISMATCH"))
A17: =Expected_MonthlyTotals!A11 | B17: =Expected_MonthlyTotals!B11 | C17: =IF($B$3,SUMIFS(PQ_MonthlyTotals!$B$2:$B$2000,PQ_MonthlyTotals!$A$2:$A$2000,$A17),"") | D17: =IF($B$3,C17-B17,"") | E17: =Expected_MonthlyTotals!D11 | F17: =IF($B$3,SUMIFS(PQ_MonthlyTotals!$D$2:$D$2000,PQ_MonthlyTotals!$A$2:$A$2000,$A17),"") | G17: =IF($B$3,F17-E17,"") | H17: =Expected_MonthlyTotals!E11 | I17: =IF($B$3,SUMIFS(PQ_MonthlyTotals!$E$2:$E$2000,PQ_MonthlyTotals!$A$2:$A$2000,$A17),"") | J17: =IF($B$3,I17-H17,"") | K17: =Expected_MonthlyTotals!H11 | L17: =IF($B$3,SUMIFS(PQ_MonthlyTotals!$H$2:$H$2000,PQ_MonthlyTotals!$A$2:$A$2000,$A17),"") | M17: =IF($B$3,L17-K17,"") | N17: =Expected_MonthlyTotals!F11 | O17: =IF($B$3,SUMIFS(PQ_MonthlyTotals!$F$2:$F$2000,PQ_MonthlyTotals!$A$2:$A$2000,$A17),"") | P17: =IF($B$3,O17-N17,"") | Q17: =Expected_MonthlyTotals!J11 | R17: =IF($B$3,SUMIFS(PQ_MonthlyTotals!$J$2:$J$2000,PQ_MonthlyTotals!$A$2:$A$2000,$A17),"") | S17: =IF($B$3,R17-Q17,"") | T17: =Expected_MonthlyTotals!K11 | U17: =IF($B$3,SUMIFS(PQ_MonthlyTotals!$K$2:$K$2000,PQ_MonthlyTotals!$A$2:$A$2000,$A17),"") | V17: =IF($B$3,U17-T17,"") | W17: =IF(NOT($B$3),"NOT LOADED",IF(AND(ABS(D17)<=$B$4,ABS(G17)<=$B$4,ABS(J17)<=$B$4,ABS(M17)<=$B$4,ABS(P17)<=$B$4,ABS(S17)<=$B$4,ABS(V17)<=$B$4),"OK","MISMATCH"))
A18: =Expected_MonthlyTotals!A12 | B18: =Expected_MonthlyTotals!B12 | C18: =IF($B$3,SUMIFS(PQ_MonthlyTotals!$B$2:$B$2000,PQ_MonthlyTotals!$A$2:$A$2000,$A18),"") | D18: =IF($B$3,C18-B18,"") | E18: =Expected_MonthlyTotals!D12 | F18: =IF($B$3,SUMIFS(PQ_MonthlyTotals!$D$2:$D$2000,PQ_MonthlyTotals!$A$2:$A$2000,$A18),"") | G18: =IF($B$3,F18-E18,"") | H18: =Expected_MonthlyTotals!E12 | I18: =IF($B$3,SUMIFS(PQ_MonthlyTotals!$E$2:$E$2000,PQ_MonthlyTotals!$A$2:$A$2000,$A18),"") | J18: =IF($B$3,I18-H18,"") | K18: =Expected_MonthlyTotals!H12 | L18: =IF($B$3,SUMIFS(PQ_MonthlyTotals!$H$2:$H$2000,PQ_MonthlyTotals!$A$2:$A$2000,$A18),"") | M18: =IF($B$3,L18-K18,"") | N18: =Expected_MonthlyTotals!F12 | O18: =IF($B$3,SUMIFS(PQ_MonthlyTotals!$F$2:$F$2000,PQ_MonthlyTotals!$A$2:$A$2000,$A18),"") | P18: =IF($B$3,O18-N18,"") | Q18: =Expected_MonthlyTotals!J12 | R18: =IF($B$3,SUMIFS(PQ_MonthlyTotals!$J$2:$J$2000,PQ_MonthlyTotals!$A$2:$A$2000,$A18),"") | S18: =IF($B$3,R18-Q18,"") | T18: =Expected_MonthlyTotals!K12 | U18: =IF($B$3,SUMIFS(PQ_MonthlyTotals!$K$2:$K$2000,PQ_MonthlyTotals!$A$2:$A$2000,$A18),"") | V18: =IF($B$3,U18-T18,"") | W18: =IF(NOT($B$3),"NOT LOADED",IF(AND(ABS(D18)<=$B$4,ABS(G18)<=$B$4,ABS(J18)<=$B$4,ABS(M18)<=$B$4,ABS(P18)<=$B$4,ABS(S18)<=$B$4,ABS(V18)<=$B$4),"OK","MISMATCH"))
A19: =Expected_MonthlyTotals!A13 | B19: =Expected_MonthlyTotals!B13 | C19: =IF($B$3,SUMIFS(PQ_MonthlyTotals!$B$2:$B$2000,PQ_MonthlyTotals!$A$2:$A$2000,$A19),"") | D19: =IF($B$3,C19-B19,"") | E19: =Expected_MonthlyTotals!D13 | F19: =IF($B$3,SUMIFS(PQ_MonthlyTotals!$D$2:$D$2000,PQ_MonthlyTotals!$A$2:$A$2000,$A19),"") | G19: =IF($B$3,F19-E19,"") | H19: =Expected_MonthlyTotals!E13 | I19: =IF($B$3,SUMIFS(PQ_MonthlyTotals!$E$2:$E$2000,PQ_MonthlyTotals!$A$2:$A$2000,$A19),"") | J19: =IF($B$3,I19-H19,"") | K19: =Expected_MonthlyTotals!H13 | L19: =IF($B$3,SUMIFS(PQ_MonthlyTotals!$H$2:$H$2000,PQ_MonthlyTotals!$A$2:$A$2000,$A19),"") | M19: =IF($B$3,L19-K19,"") | N19: =Expected_MonthlyTotals!F13 | O19: =IF($B$3,SUMIFS(PQ_MonthlyTotals!$F$2:$F$2000,PQ_MonthlyTotals!$A$2:$A$2000,$A19),"") | P19: =IF($B$3,O19-N19,"") | Q19: =Expected_MonthlyTotals!J13 | R19: =IF($B$3,SUMIFS(PQ_MonthlyTotals!$J$2:$J$2000,PQ_MonthlyTotals!$A$2:$A$2000,$A19),"") | S19: =IF($B$3,R19-Q19,"") | T19: =Expected_MonthlyTotals!K13 | U19: =IF($B$3,SUMIFS(PQ_MonthlyTotals!$K$2:$K$2000,PQ_MonthlyTotals!$A$2:$A$2000,$A19),"") | V19: =IF($B$3,U19-T19,"") | W19: =IF(NOT($B$3),"NOT LOADED",IF(AND(ABS(D19)<=$B$4,ABS(G19)<=$B$4,ABS(J19)<=$B$4,ABS(M19)<=$B$4,ABS(P19)<=$B$4,ABS(S19)<=$B$4,ABS(V19)<=$B$4),"OK","MISMATCH"))
... A31: =Expected_MonthlyTotals!A25 | B31: =Expected_MonthlyTotals!B25 | C31: =IF($B$3,SUMIFS(PQ_MonthlyTotals!$B$2:$B$2000,PQ_MonthlyTotals!$A$2:$A$2000,$A31),"") | D31: =IF($B$3,C31-B31,"") | E31: =Expected_MonthlyTotals!D25 | F31: =IF($B$3,SUMIFS(PQ_MonthlyTotals!$D$2:$D$2000,PQ_MonthlyTotals!$A$2:$A$2000,$A31),"") | G31: =IF($B$3,F31-E31,"") | H31: =Expected_MonthlyTotals!E25 | I31: =IF($B$3,SUMIFS(PQ_MonthlyTotals!$E$2:$E$2000,PQ_MonthlyTotals!$A$2:$A$2000,$A31),"") | J31: =IF($B$3,I31-H31,"") | K31: =Expected_MonthlyTotals!H25 | L31: =IF($B$3,SUMIFS(PQ_MonthlyTotals!$H$2:$H$2000,PQ_MonthlyTotals!$A$2:$A$2000,$A31),"") | M31: =IF($B$3,L31-K31,"") | N31: =Expected_MonthlyTotals!F25 | O31: =IF($B$3,SUMIFS(PQ_MonthlyTotals!$F$2:$F$2000,PQ_MonthlyTotals!$A$2:$A$2000,$A31),"") | P31: =IF($B$3,O31-N31,"") | Q31: =Expected_MonthlyTotals!J25 | R31: =IF($B$3,SUMIFS(PQ_MonthlyTotals!$J$2:$J$2000,PQ_MonthlyTotals!$A$2:$A$2000,$A31),"") | S31: =IF($B$3,R31-Q31,"") | T31: =Expected_MonthlyTotals!K25 | U31: =IF($B$3,SUMIFS(PQ_MonthlyTotals!$K$2:$K$2000,PQ_MonthlyTotals!$A$2:$A$2000,$A31),"") | V31: =IF($B$3,U31-T31,"") | W31: =IF(NOT($B$3),"NOT LOADED",IF(AND(ABS(D31)<=$B$4,ABS(G31)<=$B$4,ABS(J31)<=$B$4,ABS(M31)<=$B$4,ABS(P31)<=$B$4,ABS(S31)<=$B$4,ABS(V31)<=$B$4),"OK","MISMATCH"))
